<?xml version="1.0" ?>
<mujoco model="kitchen">
	<compiler angle="radian" autolimits="true" balanceinertia="true" boundmass="0.000001" boundinertia="0.000001"/>
	<default>
		<default class="iai_oven_area_visual">
			<geom contype="0" conaffinity="0"/>
		</default>
		<default class="iai_oven_area_collision">
			<geom rgba="0.9 0.9 0.9 1.0" group="3"/>
		</default>
	</default>
	<asset/>
	<worldbody>
		<body name="room_link" pos="0.0 0.0 0.0" quat="1.0 0.0 0.0 0.0">
			<inertial mass="0.0" pos="0.0 0.0 0.0" quat="1.0 0.0 0.0 0.0" diaginertia="0.0 0.0 0.0"/>
			<body name="oven_area_area_footprint" pos="1.8049999475479126 2.5199999809265137 0.0" quat="-1.0341155557737347e-13 0.0 0.0 1.0">
				<inertial mass="1.0" pos="0.0 0.0 0.0" quat="1.0 0.0 0.0 0.0" diaginertia="1.0 1.0 1.0"/>
				<body name="oven_area_area" pos="0.28999999165534973 0.6000000238418579 0.7549999952316284" quat="1.0 0.0 0.0 0.0">
					<inertial mass="1.0" pos="0.0 0.0 0.0" quat="1.0 0.0 0.0 0.0" diaginertia="1.0 1.0 1.0"/>
					<body name="oven_area_area_middle_upper_drawer_main" pos="0.0 0.0 0.04500000178813934" quat="1.0 0.0 0.0 0.0">
						<inertial mass="1.0" pos="0.0 0.0 0.0" quat="1.0 0.0 0.0 0.0" diaginertia="1.0 1.0 1.0"/>
						<joint name="oven_area_area_middle_upper_drawer_main_joint" type="slide" pos="-0.0 0.0 -4.163336342344337e-17" range="0.0 0.47999998927116394" axis="1.0 0.0 0.0"/>
						<body name="oven_area_area_middle_upper_drawer_handle" pos="0.33250001072883606 0.0 0.017500000074505806" quat="1.0 0.0 0.0 0.0">
							<inertial mass="1.0" pos="0.0 0.0 0.0" quat="1.0 0.0 0.0 0.0" diaginertia="1.0 1.0 1.0"/>
						</body>
					</body>
					<body name="oven_area_area_middle_lower_drawer_main" pos="0.0 0.0 -0.3149999976158142" quat="1.0 0.0 0.0 0.0">
						<inertial mass="1.0" pos="0.0 0.0 0.0" quat="1.0 0.0 0.0 0.0" diaginertia="1.0 1.0 1.0"/>
						<joint name="oven_area_area_middle_lower_drawer_main_joint" type="slide" pos="0.0 0.0 -0.0" range="0.0 0.47999998927116394" axis="1.0 0.0 0.0"/>
						<body name="oven_area_area_middle_lower_drawer_handle" pos="0.33250001072883606 0.0 0.23749999701976776" quat="1.0 0.0 0.0 0.0">
							<inertial mass="1.0" pos="0.0 0.0 0.0" quat="1.0 0.0 0.0 0.0" diaginertia="1.0 1.0 1.0"/>
						</body>
					</body>
					<body name="oven_area_area_left_drawer_main" pos="-2.220446049250313e-16 -0.44999998807907104 0.05999999865889549" quat="1.0 0.0 0.0 0.0">
						<inertial mass="1.0" pos="0.0 0.0 0.0" quat="1.0 0.0 0.0 0.0" diaginertia="1.0 1.0 1.0"/>
						<joint name="oven_area_area_left_drawer_main_joint" type="slide" pos="-2.220446049250313e-16 5.551115123125783e-17 5.551115123125783e-17" range="0.0 0.47999998927116394" axis="1.0 0.0 0.0"/>
						<body name="oven_area_area_left_drawer_handle" pos="0.35249999165534973 -4.440892098500626e-16 0.0" quat="1.0 0.0 0.0 0.0">
							<inertial mass="1.0" pos="0.0 0.0 0.0" quat="1.0 0.0 0.0 0.0" diaginertia="1.0 1.0 1.0"/>
						</body>
					</body>
					<body name="oven_area_area_right_drawer_main" pos="0.019999999552965164 0.4399999976158142 0.05000000074505806" quat="1.0 0.0 0.0 0.0">
						<inertial mass="0.10000000149011612" pos="0.0 0.0 0.0" quat="1.0 0.0 0.0 0.0" diaginertia="3.999999975690116e-08 3.999999975690116e-08 3.999999975690116e-08"/>
						<joint name="oven_area_area_right_drawer_joint" type="slide" pos="-2.0469737016526324e-16 1.6653345369377348e-16 -4.163336342344337e-17" range="0.0 0.47999998927116394" axis="0.9990314841270447 0.0 0.04400138556957245"/>
						<body name="drawer_oven_right_board0_link" pos="0.0 0.0 -0.6549999713897705" quat="1.0 0.0 0.0 0.0">
							<inertial mass="1.0" pos="0.0 0.0 0.0" quat="-0.7071067690849304 0.0 0.0 0.7071067690849304" diaginertia="0.03480416536331177 0.15355417132377625 0.17385417222976685"/>
						</body>
						<body name="drawer_oven_right_board0_barrier_left_link" pos="0.0 0.13500000536441803 -0.6200000047683716" quat="1.0 0.0 0.0 0.0">
							<inertial mass="1.0" pos="0.0 0.0 0.0" quat="-0.7071067690849304 0.0 0.0 0.7071067690849304" diaginertia="0.03480416536331177 0.15355417132377625 0.17385417222976685"/>
						</body>
						<body name="drawer_oven_right_board1_barrier_right_link" pos="2.220446049250313e-16 -0.13500000536441803 -0.29499998688697815" quat="1.0 0.0 0.0 0.0">
							<inertial mass="1.0" pos="0.0 0.0 0.0" quat="-0.7071067690849304 0.0 0.0 0.7071067690849304" diaginertia="0.03480416536331177 0.15355417132377625 0.17385417222976685"/>
						</body>
						<body name="drawer_oven_right_board2_link" pos="0.0 0.0 0.0" quat="1.0 0.0 0.0 0.0">
							<inertial mass="1.0" pos="0.0 0.0 0.0" quat="-0.7071067690849304 0.0 0.0 0.7071067690849304" diaginertia="0.03480416536331177 0.15355417132377625 0.17385417222976685"/>
						</body>
						<body name="drawer_oven_right_board2_barrier_left_link" pos="0.0 0.13500000536441803 0.03500000014901161" quat="1.0 0.0 0.0 0.0">
							<inertial mass="1.0" pos="0.0 0.0 0.0" quat="-0.7071067690849304 0.0 0.0 0.7071067690849304" diaginertia="0.03480416536331177 0.15355417132377625 0.17385417222976685"/>
						</body>
						<body name="drawer_oven_right_board3_barrier_right_link" pos="2.220446049250313e-16 -0.13500000536441803 0.36500000953674316" quat="1.0 0.0 0.0 0.0">
							<inertial mass="1.0" pos="0.0 0.0 0.0" quat="-0.7071067690849304 0.0 0.0 0.7071067690849304" diaginertia="0.03480416536331177 0.15355417132377625 0.17385417222976685"/>
						</body>
						<body name="drawer_oven_right_board0_barrier_right_link" pos="2.220446049250313e-16 -0.13500000536441803 -0.6200000047683716" quat="1.0 0.0 0.0 0.0">
							<inertial mass="1.0" pos="0.0 0.0 0.0" quat="-0.7071067690849304 0.0 0.0 0.7071067690849304" diaginertia="0.03480416536331177 0.15355417132377625 0.17385417222976685"/>
						</body>
						<body name="drawer_oven_right_board1_barrier_left_link" pos="0.0 0.13500000536441803 -0.29499998688697815" quat="1.0 0.0 0.0 0.0">
							<inertial mass="1.0" pos="0.0 0.0 0.0" quat="-0.7071067690849304 0.0 0.0 0.7071067690849304" diaginertia="0.03480416536331177 0.15355417132377625 0.17385417222976685"/>
						</body>
						<body name="drawer_oven_right_board3_link" pos="0.0 0.0 0.33000001311302185" quat="1.0 0.0 0.0 0.0">
							<inertial mass="1.0" pos="0.0 0.0 0.0" quat="-0.7071067690849304 0.0 0.0 0.7071067690849304" diaginertia="0.03480416536331177 0.15355417132377625 0.17385417222976685"/>
						</body>
						<body name="drawer_oven_right_front_link" pos="0.25 0.0 0.0" quat="1.0 0.0 0.0 0.0">
							<inertial mass="1.0" pos="0.0 0.0 0.0" quat="-0.7071067690849304 0.0 0.0 0.7071067690849304" diaginertia="0.03480416536331177 0.15355417132377625 0.17385417222976685"/>
							<body name="oven_area_area_right_drawer_handle" pos="0.05000000074505806 0.0 0.0" quat="1.0 0.0 0.0 0.0">
								<inertial mass="0.10000000149011612" pos="0.0 0.0 0.0" quat="-0.7071067690849304 0.0 0.0 0.7071067690849304" diaginertia="1.6666666624587378e-06 0.01271104160696268 0.01271104160696268"/>
							</body>
						</body>
						<body name="drawer_oven_right_board1_link" pos="0.0 0.0 -0.33000001311302185" quat="1.0 0.0 0.0 0.0">
							<inertial mass="1.0" pos="0.0 0.0 0.0" quat="-0.7071067690849304 0.0 0.0 0.7071067690849304" diaginertia="0.03480416536331177 0.15355417132377625 0.17385417222976685"/>
						</body>
						<body name="drawer_oven_right_board3_barrier_left_link" pos="0.0 0.13500000536441803 0.36500000953674316" quat="1.0 0.0 0.0 0.0">
							<inertial mass="1.0" pos="0.0 0.0 0.0" quat="-0.7071067690849304 0.0 0.0 0.7071067690849304" diaginertia="0.03480416536331177 0.15355417132377625 0.17385417222976685"/>
						</body>
						<body name="drawer_oven_right_board2_barrier_right_link" pos="2.220446049250313e-16 -0.13500000536441803 0.03500000014901161" quat="1.0 0.0 0.0 0.0">
							<inertial mass="1.0" pos="0.0 0.0 0.0" quat="-0.7071067690849304 0.0 0.0 0.7071067690849304" diaginertia="0.03480416536331177 0.15355417132377625 0.17385417222976685"/>
						</body>
					</body>
					<body name="oven_area_oven_main" pos="0.0 0.0 0.41499999165534973" quat="1.0 0.0 0.0 0.0">
						<inertial mass="1.0" pos="0.0 0.0 0.0" quat="1.0 0.0 0.0 0.0" diaginertia="1.0 1.0 1.0"/>
						<body name="oven_area_oven_panel" pos="0.27000001072883606 0.0 0.24490000307559967" quat="1.0 0.0 0.0 0.0">
							<inertial mass="1.0" pos="0.0 0.0 0.0" quat="1.0 0.0 0.0 0.0" diaginertia="1.0 1.0 1.0"/>
							<body name="oven_area_oven_knob_stove_2" pos="-2.220446049250313e-16 -0.14000000059604645 0.0" quat="0.7071067690849304 0.0 -0.7071067690849304 0.0">
								<inertial mass="1.0" pos="0.0 0.0 0.0" quat="1.0 0.0 0.0 0.0" diaginertia="1.0 1.0 1.0"/>
								<joint name="oven_area_oven_knob_stove_2_joint" type="hinge" pos="-2.220446049250313e-16 1.1102230246251565e-16 -0.0" range="0.0 3.1415927410125732" axis="0.0 0.0 1.0"/>
							</body>
							<body name="oven_area_oven_knob_stove_4" pos="0.0 0.0 0.0" quat="0.7071067690849304 0.0 -0.7071067690849304 0.0">
								<inertial mass="1.0" pos="0.0 0.0 0.0" quat="1.0 0.0 0.0 0.0" diaginertia="1.0 1.0 1.0"/>
								<joint name="oven_area_oven_knob_stove_4_joint" type="hinge" pos="0.0 0.0 -0.0" range="0.0 3.1415927410125732" axis="0.0 0.0 1.0"/>
							</body>
							<body name="oven_area_oven_knob_stove_1" pos="0.0 -0.20999999344348907 0.0" quat="0.7071067690849304 0.0 -0.7071067690849304 0.0">
								<inertial mass="1.0" pos="0.0 0.0 0.0" quat="1.0 0.0 0.0 0.0" diaginertia="1.0 1.0 1.0"/>
								<joint name="oven_area_oven_knob_stove_1_joint" type="hinge" pos="-4.018346000037365e-29 -1.942890293094024e-16 0.0" range="0.0 3.1415927410125732" axis="0.0 0.0 1.0"/>
							</body>
							<body name="oven_area_oven_knob_oven" pos="0.0 0.1599999964237213 0.0" quat="0.7071067690849304 0.0 -0.7071067690849304 0.0">
								<inertial mass="1.0" pos="0.0 0.0 0.0" quat="1.0 0.0 0.0 0.0" diaginertia="1.0 1.0 1.0"/>
								<joint name="oven_area_oven_knob_oven_joint" type="hinge" pos="-1.7221483502145608e-29 -8.326672684688674e-17 0.0" range="0.0 3.1415927410125732" axis="0.0 0.0 1.0"/>
							</body>
							<body name="oven_area_oven_knob_stove_3" pos="-2.220446049250313e-16 -0.07000000029802322 0.0" quat="0.7071067690849304 0.0 -0.7071067690849304 0.0">
								<inertial mass="1.0" pos="0.0 0.0 0.0" quat="1.0 0.0 0.0 0.0" diaginertia="1.0 1.0 1.0"/>
								<joint name="oven_area_oven_knob_stove_3_joint" type="hinge" pos="-2.220446049250313e-16 -5.551115123125783e-17 0.0" range="0.0 3.1415927410125732" axis="0.0 0.0 1.0"/>
							</body>
						</body>
						<body name="oven_area_oven_door" pos="0.2736999988555908 0.0 -0.2614000141620636" quat="0.7071067690849304 -0.7071067690849304 0.0 0.0">
							<inertial mass="1.0" pos="0.0 0.0 0.0" quat="1.0 0.0 0.0 0.0" diaginertia="1.0 1.0 1.0"/>
							<joint name="oven_area_oven_door_joint" type="hinge" pos="5.551115123125783e-17 -1.1480989001430405e-29 5.551115123125783e-17" range="0.0 0.0" axis="0.0 0.0 1.0"/>
							<body name="oven_area_oven_door_handle" pos="0.05875999853014946 -0.39803001284599304 -2.220446049250313e-16" quat="0.7071067690849304 -0.7071067690849304 0.0 0.0">
								<inertial mass="1.0" pos="0.0 0.0 0.0" quat="1.0 0.0 0.0 0.0" diaginertia="1.0 1.0 1.0"/>
							</body>
						</body>
					</body>
				</body>
			</body>
			<body name="kitchen_island_footprint" pos="-1.3650000095367432 0.5899999737739563 0.0" quat="1.0 0.0 0.0 0.0">
				<inertial mass="1.0" pos="0.0 0.0 0.0" quat="1.0 0.0 0.0 0.0" diaginertia="1.0 1.0 1.0"/>
				<body name="kitchen_island" pos="0.29750001430511475 1.1291999816894531 0.42100000381469727" quat="1.0 0.0 0.0 0.0">
					<inertial mass="1.0" pos="0.0 0.0 0.0" quat="1.0 0.0 0.0 0.0" diaginertia="1.0 1.0 1.0"/>
					<body name="kitchen_island_stove" pos="0.0 0.7657999992370605 0.43149998784065247" quat="1.0 0.0 0.0 0.0">
						<inertial mass="1.0" pos="0.0 0.0 0.0" quat="1.0 0.0 0.0 0.0" diaginertia="1.0 1.0 1.0"/>
					</body>
					<body name="kitchen_island_left_upper_drawer_main" pos="0.0024999999441206455 -0.800000011920929 0.11400000005960464" quat="1.0 0.0 0.0 0.0">
						<inertial mass="1.0" pos="0.0 0.0 0.0" quat="1.0 0.0 0.0 0.0" diaginertia="1.0 1.0 1.0"/>
						<joint name="kitchen_island_left_upper_drawer_main_joint" type="slide" pos="5.334274688628682e-17 0.0 -4.163336342344337e-17" range="0.0 0.47999998927116394" axis="1.0 0.0 0.0"/>
						<body name="kitchen_island_left_upper_drawer_handle" pos="0.33250001072883606 0.0 0.10999999940395355" quat="1.0 0.0 0.0 0.0">
							<inertial mass="1.0" pos="0.0 0.0 0.0" quat="1.0 0.0 0.0 0.0" diaginertia="1.0 1.0 1.0"/>
						</body>
					</body>
					<body name="kitchen_island_left_lower_drawer_main" pos="0.0024999999441206455 -0.800000011920929 -0.17599999904632568" quat="1.0 0.0 0.0 0.0">
						<inertial mass="1.0" pos="0.0 0.0 0.0" quat="1.0 0.0 0.0 0.0" diaginertia="1.0 1.0 1.0"/>
						<joint name="kitchen_island_left_lower_drawer_main_joint" type="slide" pos="5.334274688628682e-17 0.0 0.0" range="0.0 0.47999998927116394" axis="1.0 0.0 0.0"/>
						<body name="kitchen_island_left_lower_drawer_handle" pos="0.33250001072883606 0.0 0.10999999940395355" quat="1.0 0.0 0.0 0.0">
							<inertial mass="1.0" pos="0.0 0.0 0.0" quat="1.0 0.0 0.0 0.0" diaginertia="1.0 1.0 1.0"/>
						</body>
					</body>
					<body name="kitchen_island_middle_panel" pos="0.27250000834465027 0.0 0.32899999618530273" quat="1.0 0.0 0.0 0.0">
						<inertial mass="1.0" pos="0.0 0.0 0.0" quat="1.0 0.0 0.0 0.0" diaginertia="1.0 1.0 1.0"/>
					</body>
					<body name="kitchen_island_middle_lower_drawer_main" pos="0.0024999999441206455 0.0 -0.17599999904632568" quat="1.0 0.0 0.0 0.0">
						<inertial mass="1.0" pos="0.0 0.0 0.0" quat="1.0 0.0 0.0 0.0" diaginertia="1.0 1.0 1.0"/>
						<joint name="kitchen_island_middle_lower_drawer_main_joint" type="slide" pos="5.334274688628682e-17 0.0 0.0" range="0.0 0.47999998927116394" axis="1.0 0.0 0.0"/>
						<body name="kitchen_island_middle_lower_drawer_handle" pos="0.33250001072883606 0.0 0.10999999940395355" quat="1.0 0.0 0.0 0.0">
							<inertial mass="1.0" pos="0.0 0.0 0.0" quat="1.0 0.0 0.0 0.0" diaginertia="1.0 1.0 1.0"/>
						</body>
					</body>
					<body name="kitchen_island_right_panel" pos="0.27250000834465027 0.800000011920929 0.32899999618530273" quat="1.0 0.0 0.0 0.0">
						<inertial mass="1.0" pos="0.0 0.0 0.0" quat="1.0 0.0 0.0 0.0" diaginertia="1.0 1.0 1.0"/>
					</body>
					<body name="kitchen_island_right_lower_drawer_main" pos="0.0024999999441206455 0.800000011920929 -0.17599999904632568" quat="1.0 0.0 0.0 0.0">
						<inertial mass="1.0" pos="0.0 0.0 0.0" quat="1.0 0.0 0.0 0.0" diaginertia="1.0 1.0 1.0"/>
						<joint name="kitchen_island_right_lower_drawer_main_joint" type="slide" pos="5.334274688628682e-17 2.220446049250313e-16 0.0" range="0.0 0.47999998927116394" axis="1.0 0.0 0.0"/>
						<body name="kitchen_island_right_lower_drawer_handle" pos="0.33250001072883606 0.0 0.10999999940395355" quat="1.0 0.0 0.0 0.0">
							<inertial mass="1.0" pos="0.0 0.0 0.0" quat="1.0 0.0 0.0 0.0" diaginertia="1.0 1.0 1.0"/>
						</body>
					</body>
					<body name="kitchen_island_surface" pos="0.0 0.0 0.41999998688697815" quat="1.0 0.0 0.0 0.0">
						<inertial mass="1.0" pos="0.0 0.0 0.0" quat="1.0 0.0 0.0 0.0" diaginertia="1.0 1.0 1.0"/>
					</body>
					<body name="kitchen_island_middle_upper_drawer_main" pos="0.0024999999441206455 0.0 0.11400000005960464" quat="1.0 0.0 0.0 0.0">
						<inertial mass="1.0" pos="0.0 0.0 0.0" quat="1.0 0.0 0.0 0.0" diaginertia="1.0 1.0 1.0"/>
						<joint name="kitchen_island_middle_upper_drawer_main_joint" type="slide" pos="5.334274688628682e-17 0.0 -4.163336342344337e-17" range="0.0 0.47999998927116394" axis="1.0 0.0 0.0"/>
						<body name="kitchen_island_middle_upper_drawer_handle" pos="0.33250001072883606 0.0 0.10999999940395355" quat="1.0 0.0 0.0 0.0">
							<inertial mass="1.0" pos="0.0 0.0 0.0" quat="1.0 0.0 0.0 0.0" diaginertia="1.0 1.0 1.0"/>
						</body>
					</body>
					<body name="kitchen_island_right_upper_drawer_main" pos="0.0024999999441206455 0.800000011920929 0.11400000005960464" quat="1.0 0.0 0.0 0.0">
						<inertial mass="1.0" pos="0.0 0.0 0.0" quat="1.0 0.0 0.0 0.0" diaginertia="1.0 1.0 1.0"/>
						<joint name="kitchen_island_right_upper_drawer_main_joint" type="slide" pos="5.334274688628682e-17 2.220446049250313e-16 -4.163336342344337e-17" range="0.0 0.47999998927116394" axis="1.0 0.0 0.0"/>
						<body name="kitchen_island_right_upper_drawer_handle" pos="0.33250001072883606 0.0 0.10999999940395355" quat="1.0 0.0 0.0 0.0">
							<inertial mass="1.0" pos="0.0 0.0 0.0" quat="1.0 0.0 0.0 0.0" diaginertia="1.0 1.0 1.0"/>
						</body>
					</body>
					<body name="kitchen_island_left_panel" pos="0.27250000834465027 -0.800000011920929 0.32899999618530273" quat="1.0 0.0 0.0 0.0">
						<inertial mass="1.0" pos="0.0 0.0 0.0" quat="1.0 0.0 0.0 0.0" diaginertia="1.0 1.0 1.0"/>
					</body>
				</body>
			</body>
			<body name="fridge_area_footprint" pos="1.8250000476837158 -0.7400000095367432 0.0" quat="-1.0341155557737347e-13 0.0 0.0 1.0">
				<inertial mass="1.0" pos="0.0 0.0 0.0" quat="1.0 0.0 0.0 0.0" diaginertia="1.0 1.0 1.0"/>
				<body name="fridge_area" pos="0.28999999165534973 0.30000001192092896 0.7400000095367432" quat="1.0 0.0 0.0 0.0">
					<inertial mass="1.0" pos="0.0 0.0 0.0" quat="1.0 0.0 0.0 0.0" diaginertia="1.0 1.0 1.0"/>
					<body name="iai_fridge_main" pos="0.0 0.0 0.0" quat="1.0 0.0 0.0 0.0">
						<inertial mass="1.0" pos="0.0 0.0 0.0" quat="1.0 0.0 0.0 0.0" diaginertia="1.0 1.0 1.0"/>
						<body name="iai_fridge_door" pos="0.28999999165534973 0.30000001192092896 0.24500000476837158" quat="1.0 0.0 0.0 0.0">
							<inertial mass="1.0" pos="0.0 0.0 0.0" quat="1.0 0.0 0.0 0.0" diaginertia="1.0 1.0 1.0"/>
							<joint name="iai_fridge_door_joint" type="hinge" pos="-1.6653345369377348e-16 5.551115123125783e-17 -0.0" range="0.0 1.5707963705062866" axis="0.0 0.0 1.0"/>
							<body name="iai_fridge_door_handle" pos="0.05999999865889549 -0.5699999928474426 0.0" quat="1.0 0.0 0.0 0.0">
								<inertial mass="1.0" pos="0.0 0.0 0.0" quat="1.0 0.0 0.0 0.0" diaginertia="1.0 1.0 1.0"/>
							</body>
						</body>
					</body>
					<body name="fridge_area_lower_drawer_main" pos="0.0 0.0 -0.41749998927116394" quat="1.0 0.0 0.0 0.0">
						<inertial mass="1.0" pos="0.0 0.0 0.0" quat="1.0 0.0 0.0 0.0" diaginertia="1.0 1.0 1.0"/>
						<joint name="fridge_area_lower_drawer_main_joint" type="slide" pos="0.0 0.0 -0.0" range="0.0 0.47999998927116394" axis="1.0 0.0 0.0"/>
						<body name="fridge_area_lower_drawer_handle" pos="0.33250001072883606 0.0 0.10999999940395355" quat="1.0 0.0 0.0 0.0">
							<inertial mass="1.0" pos="0.0 0.0 0.0" quat="1.0 0.0 0.0 0.0" diaginertia="1.0 1.0 1.0"/>
						</body>
					</body>
				</body>
			</body>
			<body name="table_area" pos="-2.700000047683716 -0.6000000238418579 0.0" quat="-1.0341155557737347e-13 0.0 0.0 1.0">
				<inertial mass="1.0" pos="0.0 0.0 0.0" quat="1.0 0.0 0.0 0.0" diaginertia="1.0 1.0 1.0"/>
			</body>
			<body name="sink_area_footprint" pos="1.8250000476837158 1.3200000524520874 0.0" quat="-1.0341155557737347e-13 0.0 0.0 1.0">
				<inertial mass="1.0" pos="0.0 0.0 0.0" quat="1.0 0.0 0.0 0.0" diaginertia="1.0 1.0 1.0"/>
				<body name="sink_area" pos="0.28999999165534973 1.0299999713897705 0.4099999964237213" quat="1.0 0.0 0.0 0.0">
					<inertial mass="1.0" pos="0.0 0.0 0.0" quat="1.0 0.0 0.0 0.0" diaginertia="1.0 1.0 1.0"/>
					<body name="sink_area_sink" pos="0.004999999888241291 0.4699999988079071 0.4413999915122986" quat="1.0 0.0 0.0 0.0">
						<inertial mass="1.0" pos="0.0 0.0 0.0" quat="1.0 0.0 0.0 0.0" diaginertia="1.0 1.0 1.0"/>
					</body>
					<body name="sink_area_trash_drawer_main" pos="0.009999999776482582 0.699999988079071 -0.014999999664723873" quat="1.0 0.0 0.0 0.0">
						<inertial mass="1.0" pos="0.0 0.0 0.0" quat="1.0 0.0 0.0 0.0" diaginertia="1.0 1.0 1.0"/>
						<joint name="sink_area_trash_drawer_main_joint" type="slide" pos="8.673617379884035e-18 -1.7939044374339527e-30 1.3877787807814457e-17" range="0.0 0.47999998927116394" axis="1.0 0.0 0.0"/>
						<body name="sink_area_trash_drawer_handle" pos="0.33250001072883606 0.0 0.23749999701976776" quat="1.0 0.0 0.0 0.0">
							<inertial mass="1.0" pos="0.0 0.0 0.0" quat="1.0 0.0 0.0 0.0" diaginertia="1.0 1.0 1.0"/>
						</body>
					</body>
					<body name="sink_area_left_upper_drawer_main" pos="0.009999999776482582 -0.6000000238418579 0.3449999988079071" quat="1.0 0.0 0.0 0.0">
						<inertial mass="1.0" pos="0.0 0.0 0.0" quat="1.0 0.0 0.0 0.0" diaginertia="1.0 1.0 1.0"/>
						<joint name="sink_area_left_upper_drawer_main_joint" type="slide" pos="8.673617379884035e-18 1.1102230246251565e-16 5.551115123125783e-17" range="0.0 0.47999998927116394" axis="1.0 0.0 0.0"/>
						<body name="sink_area_left_upper_drawer_handle" pos="0.33250001072883606 0.0 0.017500000074505806" quat="1.0 0.0 0.0 0.0">
							<inertial mass="1.0" pos="0.0 0.0 0.0" quat="1.0 0.0 0.0 0.0" diaginertia="1.0 1.0 1.0"/>
						</body>
					</body>
					<body name="sink_area_left_middle_drawer_main" pos="0.009999999776482582 -0.6000000238418579 0.11999999731779099" quat="1.0 0.0 0.0 0.0">
						<inertial mass="1.0" pos="0.0 0.0 0.0" quat="1.0 0.0 0.0 0.0" diaginertia="1.0 1.0 1.0"/>
						<joint name="sink_area_left_middle_drawer_main_joint" type="slide" pos="8.673617379884035e-18 1.1102230246251565e-16 -5.551115123125783e-17" range="0.0 0.47999998927116394" axis="1.0 0.0 0.0"/>
						<body name="sink_area_left_middle_drawer_handle" pos="0.33250001072883606 0.0 0.10999999940395355" quat="1.0 0.0 0.0 0.0">
							<inertial mass="1.0" pos="0.0 0.0 0.0" quat="1.0 0.0 0.0 0.0" diaginertia="1.0 1.0 1.0"/>
						</body>
					</body>
					<body name="sink_area_left_bottom_drawer_main" pos="0.009999999776482582 -0.6000000238418579 -0.18000000715255737" quat="1.0 0.0 0.0 0.0">
						<inertial mass="1.0" pos="0.0 0.0 0.0" quat="1.0 0.0 0.0 0.0" diaginertia="1.0 1.0 1.0"/>
						<joint name="sink_area_left_bottom_drawer_main_joint" type="slide" pos="8.673617379884035e-18 1.1102230246251565e-16 -0.0" range="0.0 0.47999998927116394" axis="1.0 0.0 0.0"/>
						<body name="sink_area_left_bottom_drawer_handle" pos="0.33250001072883606 0.0 0.10999999940395355" quat="1.0 0.0 0.0 0.0">
							<inertial mass="1.0" pos="0.0 0.0 0.0" quat="1.0 0.0 0.0 0.0" diaginertia="1.0 1.0 1.0"/>
						</body>
					</body>
					<body name="sink_area_dish_washer_main" pos="0.009999999776482582 0.10000000149011612 0.04399999976158142" quat="1.0 0.0 0.0 0.0">
						<inertial mass="1.0" pos="0.0 0.0 0.0" quat="1.0 0.0 0.0 0.0" diaginertia="1.0 1.0 1.0"/>
						<joint name="sink_area_dish_washer_main_joint" type="hinge" pos="8.673617379884035e-18 2.7755575615628914e-17 1.3877787807814457e-17" range="0.0 0.0" axis="1.0 0.0 0.0"/>
						<body name="sink_area_dish_washer_door" pos="0.27000001072883606 0.0 -0.32499998807907104" quat="0.7071067690849304 -0.7071067690849304 0.0 0.0">
							<inertial mass="1.0" pos="0.0 0.0 0.0" quat="1.0 0.0 0.0 0.0" diaginertia="1.0 1.0 1.0"/>
							<joint name="sink_area_dish_washer_door_joint" type="hinge" pos="0.0 0.0 0.0" range="0.0 0.0" axis="0.0 0.0 1.0"/>
							<body name="sink_area_dish_washer_door_handle" pos="0.0625 -0.6324999928474426 0.0" quat="0.7071067690849304 -0.7071067690849304 0.0 0.0">
								<inertial mass="1.0" pos="0.0 0.0 0.0" quat="1.0 0.0 0.0 0.0" diaginertia="1.0 1.0 1.0"/>
							</body>
						</body>
					</body>
					<body name="sink_area_surface" pos="0.0 0.0 0.4300000071525574" quat="1.0 0.0 0.0 0.0">
						<inertial mass="1.0" pos="0.0 0.0 0.0" quat="1.0 0.0 0.0 0.0" diaginertia="1.0 1.0 1.0"/>
					</body>
					<body name="sink_area_right_panel" pos="0.2800000011920929 0.699999988079071 0.35499998927116394" quat="1.0 0.0 0.0 0.0">
						<inertial mass="1.0" pos="0.0 0.0 0.0" quat="1.0 0.0 0.0 0.0" diaginertia="1.0 1.0 1.0"/>
					</body>
				</body>
			</body>
		</body>
	</worldbody>
	<equality/>
</mujoco>
