<?xml version="1.0" ?>
<mujoco model="pr2">
	<compiler angle="radian" autolimits="true" balanceinertia="true" boundmass="0.000001" boundinertia="0.000001"/>
	<default>
		<default class="pr2_visual">
			<geom contype="0" conaffinity="0"/>
		</default>
		<default class="pr2_collision">
			<geom rgba="0.9 0.9 0.9 1.0" group="3"/>
		</default>
	</default>
	<asset/>
	<worldbody>
		<body name="base_footprint" pos="0.0 0.0 0.0" quat="1.0 0.0 0.0 0.0">
			<inertial mass="1.0" pos="0.0 0.0 0.0" quat="1.0 0.0 0.0 0.0" diaginertia="0.009999999776482582 0.009999999776482582 0.009999999776482582"/>
			<freejoint/>
			<body name="base_link" pos="0.0 0.0 0.050999999046325684" quat="1.0 0.0 0.0 0.0">
				<inertial mass="116.0" pos="-0.061000000685453415 0.0 0.14650000631809235" quat="0.8497045636177063 0.007924478501081467 0.5271715521812439 -0.005430426448583603" diaginertia="3.0417723655700684 5.66924524307251 6.293884754180908"/>
				<body name="base_laser_link" pos="0.2750000059604645 0.0 0.25200000405311584" quat="1.0 0.0 0.0 0.0">
					<inertial mass="0.0010000000474974513" pos="0.0 0.0 0.0" quat="-0.7071067690849304 0.0 0.0 0.7071067690849304" diaginertia="9.999999974752427e-07 9.999999747378752e-05 9.999999747378752e-05"/>
				</body>
				<body name="fr_caster_rotation_link" pos="0.22460000216960907 -0.22460000216960907 0.028200000524520874" quat="1.0 0.0 0.0 0.0">
					<inertial mass="3.4730820655822754" pos="0.0 0.0 0.07000000029802322" quat="-0.4079904556274414 0.2716773748397827 0.6657471060752869 0.5625975728034973" diaginertia="0.011456840671598911 0.012544593773782253 0.015392469242215157"/>
					<joint name="fr_caster_rotation_joint" type="hinge" pos="0.0 0.0 3.469446951953614e-18" axis="0.0 0.0 1.0"/>
					<body name="fr_caster_r_wheel_link" pos="0.0 -0.04899999871850014 0.0" quat="1.0 0.0 0.0 0.0">
						<inertial mass="0.44036000967025757" pos="0.0 0.0 0.0" quat="-0.4079904556274414 0.2716773748397827 0.6657471060752869 0.5625975728034973" diaginertia="0.011456840671598911 0.012544593773782253 0.015392469242215157"/>
						<joint name="fr_caster_r_wheel_joint" type="hinge" pos="0.0 1.3877787807814457e-17 0.0" axis="0.0 1.0 0.0"/>
					</body>
					<body name="fr_caster_l_wheel_link" pos="0.0 0.04899999871850014 0.0" quat="1.0 0.0 0.0 0.0">
						<inertial mass="0.44036000967025757" pos="0.0 0.0 0.0" quat="-0.4079904556274414 0.2716773748397827 0.6657471060752869 0.5625975728034973" diaginertia="0.011456840671598911 0.012544593773782253 0.015392469242215157"/>
						<joint name="fr_caster_l_wheel_joint" type="hinge" pos="0.0 -1.3877787807814457e-17 0.0" axis="0.0 1.0 0.0"/>
					</body>
				</body>
				<body name="br_caster_rotation_link" pos="-0.22460000216960907 -0.22460000216960907 0.028200000524520874" quat="1.0 0.0 0.0 0.0">
					<inertial mass="3.4730820655822754" pos="0.0 0.0 0.07000000029802322" quat="-0.4079904556274414 0.2716773748397827 0.6657471060752869 0.5625975728034973" diaginertia="0.011456840671598911 0.012544593773782253 0.015392469242215157"/>
					<joint name="br_caster_rotation_joint" type="hinge" pos="0.0 0.0 3.469446951953614e-18" axis="0.0 0.0 1.0"/>
					<body name="br_caster_r_wheel_link" pos="0.0 -0.04899999871850014 0.0" quat="1.0 0.0 0.0 0.0">
						<inertial mass="0.44036000967025757" pos="0.0 0.0 0.0" quat="-0.4079904556274414 0.2716773748397827 0.6657471060752869 0.5625975728034973" diaginertia="0.011456840671598911 0.012544593773782253 0.015392469242215157"/>
						<joint name="br_caster_r_wheel_joint" type="hinge" pos="0.0 1.3877787807814457e-17 0.0" axis="0.0 1.0 0.0"/>
					</body>
					<body name="br_caster_l_wheel_link" pos="0.0 0.04899999871850014 0.0" quat="1.0 0.0 0.0 0.0">
						<inertial mass="0.44036000967025757" pos="0.0 0.0 0.0" quat="-0.4079904556274414 0.2716773748397827 0.6657471060752869 0.5625975728034973" diaginertia="0.011456840671598911 0.012544593773782253 0.015392469242215157"/>
						<joint name="br_caster_l_wheel_joint" type="hinge" pos="0.0 -1.3877787807814457e-17 0.0" axis="0.0 1.0 0.0"/>
					</body>
				</body>
				<body name="torso_lift_motor_screw_link" pos="-0.15000000596046448 0.0 0.699999988079071" quat="1.0 0.0 0.0 0.0">
					<inertial mass="1.0" pos="0.0 0.0 0.0" quat="1.0 0.0 0.0 0.0" diaginertia="0.0010000000474974513 0.0010000000474974513 0.0010000000474974513"/>
					<joint name="torso_lift_motor_screw_joint" type="hinge" pos="0.0 0.0 0.0" axis="0.0 0.0 1.0"/>
				</body>
				<body name="base_bellow_link" pos="-0.28999999165534973 0.0 0.800000011920929" quat="1.0 0.0 0.0 0.0">
					<inertial mass="1.0" pos="0.0 0.0 0.0" quat="1.0 0.0 0.0 0.0" diaginertia="0.009999999776482582 0.009999999776482582 0.009999999776482582"/>
				</body>
				<body name="fl_caster_rotation_link" pos="0.22460000216960907 0.22460000216960907 0.028200000524520874" quat="1.0 0.0 0.0 0.0">
					<inertial mass="3.4730820655822754" pos="0.0 0.0 0.07000000029802322" quat="-0.4079904556274414 0.2716773748397827 0.6657471060752869 0.5625975728034973" diaginertia="0.011456840671598911 0.012544593773782253 0.015392469242215157"/>
					<joint name="fl_caster_rotation_joint" type="hinge" pos="0.0 0.0 3.469446951953614e-18" axis="0.0 0.0 1.0"/>
					<body name="fl_caster_r_wheel_link" pos="0.0 -0.04899999871850014 0.0" quat="1.0 0.0 0.0 0.0">
						<inertial mass="0.44036000967025757" pos="0.0 0.0 0.0" quat="-0.4079904556274414 0.2716773748397827 0.6657471060752869 0.5625975728034973" diaginertia="0.011456840671598911 0.012544593773782253 0.015392469242215157"/>
						<joint name="fl_caster_r_wheel_joint" type="hinge" pos="0.0 1.3877787807814457e-17 0.0" axis="0.0 1.0 0.0"/>
					</body>
					<body name="fl_caster_l_wheel_link" pos="0.0 0.04899999871850014 0.0" quat="1.0 0.0 0.0 0.0">
						<inertial mass="0.44036000967025757" pos="0.0 0.0 0.0" quat="-0.4079904556274414 0.2716773748397827 0.6657471060752869 0.5625975728034973" diaginertia="0.011456840671598911 0.012544593773782253 0.015392469242215157"/>
						<joint name="fl_caster_l_wheel_joint" type="hinge" pos="0.0 -1.3877787807814457e-17 0.0" axis="0.0 1.0 0.0"/>
					</body>
				</body>
				<body name="torso_lift_link" pos="-0.05000000074505806 0.0 0.739674985408783" quat="1.0 0.0 0.0 0.0">
					<inertial mass="36.248046875" pos="-0.10000000149011612 0.0 -0.0885000005364418" quat="0.6815678477287292 0.0027680164203047752 0.7317057847976685 0.008017218671739101" diaginertia="0.5145807266235352 2.5104501247406006 2.7830748558044434"/>
					<joint name="torso_lift_joint" type="slide" pos="0.0 0.0 0.0" range="0.0 0.33000001311302185" axis="0.0 0.0 1.0"/>
					<body name="r_torso_lift_side_plate_link" pos="0.05350000038743019 -0.20928500592708588 0.17662499845027924" quat="1.0 0.0 0.0 0.0">
						<inertial mass="0.10000000149011612" pos="-0.0625 0.0 0.05000000074505806" quat="1.0 0.0 0.0 0.0" diaginertia="0.0010000000474974513 0.0010000000474974513 0.0010000000474974513"/>
					</body>
					<body name="head_pan_link" pos="-0.017069999128580093 0.0 0.38144999742507935" quat="1.0 0.0 0.0 0.0">
						<inertial mass="6.339000225067139" pos="0.010906999930739403 0.031693000346422195 0.09050700068473816" quat="0.9933208227157593 0.09740236401557922 0.05015663057565689 -0.036205992102622986" diaginertia="0.03217979893088341 0.04612261801958084 0.05839352682232857"/>
						<joint name="head_pan_joint" type="hinge" pos="3.469446951953614e-18 0.0 -5.551115123125783e-17" range="-3.006999969482422 3.006999969482422" axis="0.0 0.0 1.0"/>
						<body name="head_tilt_link" pos="0.06800000369548798 0.0 0.0" quat="1.0 0.0 0.0 0.0">
							<inertial mass="4.479000091552734" pos="0.0017160000279545784 -0.01955600082874298 0.05500200018286705" quat="0.9944794774055481 -0.10440601408481598 -0.0007060912903398275 -0.010463757440447807" diaginertia="0.024210046976804733 0.05414252355694771 0.06790011376142502"/>
							<joint name="head_tilt_joint" type="hinge" pos="0.0 0.0 0.0" range="-0.47123798727989197 1.3962599039077759" axis="0.0 1.0 0.0"/>
							<body name="head_plate_frame" pos="0.02319999970495701 0.0 0.06449999660253525" quat="1.0 0.0 0.0 0.0">
								<inertial mass="0.009999999776482582" pos="0.0 0.0 0.0" quat="1.0 0.0 0.0 0.0" diaginertia="0.0010000000474974513 0.0010000000474974513 0.0010000000474974513"/>
								<body name="projector_wg6802418_frame" pos="0.0 0.10999999940395355 0.05460000038146973" quat="1.0 0.0 0.0 0.0">
									<inertial mass="0.009999999776482582" pos="0.0 0.0 0.0" quat="1.0 0.0 0.0 0.0" diaginertia="0.0010000000474974513 0.0010000000474974513 0.0010000000474974513"/>
									<body name="projector_wg6802418_child_frame" pos="0.0 0.0 0.0" quat="0.7071067690849304 0.0 -0.7071067690849304 0.0">
										<inertial mass="0.009999999776482582" pos="0.0 0.0 0.0" quat="1.0 0.0 0.0 0.0" diaginertia="0.0010000000474974513 0.0010000000474974513 0.0010000000474974513"/>
									</body>
								</body>
								<body name="head_mount_link" pos="-0.1379999965429306 0.0 0.09099999815225601" quat="1.0 0.0 0.0 0.0">
									<inertial mass="0.10000000149011612" pos="0.0 0.0 0.0" quat="1.0 0.0 0.0 0.0" diaginertia="0.009999999776482582 0.009999999776482582 0.009999999776482582"/>
									<body name="head_mount_prosilica_link" pos="-0.04645700007677078 0.012500000186264515 0.08892100304365158" quat="1.0 0.0 0.0 0.0">
										<inertial mass="0.10000000149011612" pos="0.0 0.0 0.0" quat="1.0 0.0 0.0 0.0" diaginertia="0.009999999776482582 0.009999999776482582 0.009999999776482582"/>
										<body name="head_mount_prosilica_optical_frame" pos="0.0 0.0 0.0" quat="0.5 -0.5 0.5 -0.5">
											<inertial mass="0.0" pos="0.0 0.0 0.0" quat="1.0 0.0 0.0 0.0" diaginertia="0.0 0.0 0.0"/>
										</body>
									</body>
									<body name="head_mount_kinect_ir_link" pos="-0.032267000526189804 0.012500000186264515 0.13645300269126892" quat="1.0 0.0 0.0 0.0">
										<inertial mass="0.10000000149011612" pos="0.0 0.0 0.0" quat="1.0 0.0 0.0 0.0" diaginertia="0.009999999776482582 0.009999999776482582 0.009999999776482582"/>
										<body name="head_mount_kinect_rgb_link" pos="-0.01127498410642147 -0.02459556609392166 -0.010102623142302036" quat="0.9998286962509155 -0.0032123816199600697 -0.01813780516386032 -0.0018065612530335784">
											<inertial mass="0.10000000149011612" pos="0.0 0.0 0.0" quat="1.0 0.0 0.0 0.0" diaginertia="0.009999999776482582 0.009999999776482582 0.009999999776482582"/>
											<body name="head_mount_kinect_rgb_optical_frame" pos="0.0 0.0 0.0" quat="0.5 -0.5 0.5 -0.5">
												<inertial mass="0.0" pos="0.0 0.0 0.0" quat="1.0 0.0 0.0 0.0" diaginertia="0.0 0.0 0.0"/>
											</body>
										</body>
										<body name="head_mount_kinect_ir_optical_frame" pos="0.0 0.009999999776482582 0.0" quat="0.5 -0.5 0.5 -0.5">
											<inertial mass="0.0" pos="0.0 0.0 0.0" quat="1.0 0.0 0.0 0.0" diaginertia="0.0 0.0 0.0"/>
										</body>
									</body>
								</body>
								<body name="sensor_mount_link" pos="0.0 0.0 0.0" quat="1.0 0.0 0.0 0.0">
									<inertial mass="0.05000000074505806" pos="0.0 0.0 0.0" quat="1.0 0.0 0.0 0.0" diaginertia="0.0010000000474974513 0.0010000000474974513 0.009999999776482582"/>
									<body name="double_stereo_link" pos="0.0 0.0 0.0" quat="1.0 0.0 0.0 0.0">
										<inertial mass="0.10000000149011612" pos="0.0 0.0 0.0" quat="1.0 0.0 0.0 0.0" diaginertia="0.0010000000474974513 0.0010000000474974513 0.009999999776482582"/>
										<body name="narrow_stereo_link" pos="0.04311307147145271 0.059341371059417725 0.05272095650434494" quat="0.9999792575836182 -0.002184632234275341 -0.0060007693246006966 0.0008530368213541806">
											<inertial mass="0.10000000149011612" pos="0.0 0.0 0.0" quat="1.0 0.0 0.0 0.0" diaginertia="0.009999999776482582 0.009999999776482582 0.009999999776482582"/>
											<body name="narrow_stereo_l_stereo_camera_frame" pos="1.3877787807814457e-17 -1.3877787807814457e-17 0.0" quat="1.0 -2.168404344971009e-19 -1.2037062152420224e-35 -5.421010862427522e-20">
												<inertial mass="0.009999999776482582" pos="0.0 0.0 0.0" quat="1.0 0.0 0.0 0.0" diaginertia="0.0010000000474974513 0.0010000000474974513 0.0010000000474974513"/>
												<body name="narrow_stereo_r_stereo_camera_frame" pos="1.3877787807814457e-17 -0.09000000357627869 0.0" quat="1.0 -2.168404344971009e-19 -1.2037062152420224e-35 -5.421010862427522e-20">
													<inertial mass="0.009999999776482582" pos="0.0 0.0 0.0" quat="1.0 0.0 0.0 0.0" diaginertia="0.0010000000474974513 0.0010000000474974513 0.0010000000474974513"/>
													<body name="narrow_stereo_r_stereo_camera_optical_frame" pos="0.0 6.938893903907228e-18 0.0" quat="0.5 -0.5 0.5 -0.5">
														<inertial mass="0.0" pos="0.0 0.0 0.0" quat="1.0 0.0 0.0 0.0" diaginertia="0.0 0.0 0.0"/>
													</body>
												</body>
												<body name="narrow_stereo_l_stereo_camera_optical_frame" pos="1.3877787807814457e-17 -1.3877787807814457e-17 0.0" quat="0.5 -0.5 0.5 -0.5">
													<inertial mass="0.0" pos="0.0 0.0 0.0" quat="1.0 0.0 0.0 0.0" diaginertia="0.0 0.0 0.0"/>
												</body>
											</body>
											<body name="narrow_stereo_optical_frame" pos="1.3877787807814457e-17 -1.3877787807814457e-17 0.0" quat="0.5 -0.5 0.5 -0.5">
												<inertial mass="0.0" pos="0.0 0.0 0.0" quat="1.0 0.0 0.0 0.0" diaginertia="0.0 0.0 0.0"/>
											</body>
										</body>
										<body name="wide_stereo_link" pos="0.04654507711529732 0.02805158868432045 0.05233285576105118" quat="0.9998937845230103 -0.0024621246848255396 -0.008091340772807598 0.011871942318975925">
											<inertial mass="0.10000000149011612" pos="0.0 0.0 0.0" quat="1.0 0.0 0.0 0.0" diaginertia="0.009999999776482582 0.009999999776482582 0.009999999776482582"/>
											<body name="wide_stereo_l_stereo_camera_frame" pos="0.0 6.938893903907228e-18 0.0" quat="1.0 -8.673617379884035e-19 8.673617379884035e-19 -3.3881317890172014e-21">
												<inertial mass="0.009999999776482582" pos="0.0 0.0 0.0" quat="1.0 0.0 0.0 0.0" diaginertia="0.0010000000474974513 0.0010000000474974513 0.0010000000474974513"/>
												<body name="wide_stereo_r_stereo_camera_frame" pos="0.0 -0.09000000357627869 0.0" quat="1.0 -8.673617379884035e-19 8.673617379884035e-19 -3.3881317890172014e-21">
													<inertial mass="0.009999999776482582" pos="0.0 0.0 0.0" quat="1.0 0.0 0.0 0.0" diaginertia="0.0010000000474974513 0.0010000000474974513 0.0010000000474974513"/>
													<body name="wide_stereo_r_stereo_camera_optical_frame" pos="0.0 0.0 2.220446049250313e-16" quat="0.5 -0.5 0.5 -0.5">
														<inertial mass="0.0" pos="0.0 0.0 0.0" quat="1.0 0.0 0.0 0.0" diaginertia="0.0 0.0 0.0"/>
													</body>
												</body>
												<body name="wide_stereo_l_stereo_camera_optical_frame" pos="0.0 6.938893903907228e-18 0.0" quat="0.5 -0.5 0.5 -0.5">
													<inertial mass="0.0" pos="0.0 0.0 0.0" quat="1.0 0.0 0.0 0.0" diaginertia="0.0 0.0 0.0"/>
												</body>
											</body>
											<body name="wide_stereo_optical_frame" pos="0.0 6.938893903907228e-18 0.0" quat="0.5 -0.5 0.5 -0.5">
												<inertial mass="0.0" pos="0.0 0.0 0.0" quat="1.0 0.0 0.0 0.0" diaginertia="0.0 0.0 0.0"/>
											</body>
										</body>
									</body>
									<body name="high_def_frame" pos="0.04449086636304855 -0.11099167168140411 0.0573396198451519" quat="0.999977171421051 -0.005490696988999844 -0.003620728850364685 0.0015635887393727899">
										<inertial mass="0.009999999776482582" pos="0.0 0.0 0.0" quat="1.0 0.0 0.0 0.0" diaginertia="0.0010000000474974513 0.0010000000474974513 0.0010000000474974513"/>
										<body name="high_def_optical_frame" pos="1.3877787807814457e-17 0.0 -2.220446049250313e-16" quat="0.5 -0.5 0.5 -0.5">
											<inertial mass="0.009999999776482582" pos="0.0 0.0 0.0" quat="1.0 0.0 0.0 0.0" diaginertia="0.0010000000474974513 0.0010000000474974513 0.0010000000474974513"/>
											<body name="head_mount_kinect2_rgb_optical_frame" pos="-0.01781499944627285 -0.06464800238609314 -0.03716399893164635" quat="0.9999435544013977 -0.01024716254323721 5.282440542941913e-05 0.0027986846398562193">
												<inertial mass="0.0" pos="0.0 0.0 0.0" quat="1.0 0.0 0.0 0.0" diaginertia="0.0 0.0 0.0"/>
												<body name="head_mount_kinect2_ir_optical_frame" pos="-0.05097299441695213 0.00017844406829681247 0.0013319123536348343" quat="0.9999947547912598 0.0011530707124620676 0.0028173166792839766 0.0011007614666596055">
													<inertial mass="0.0" pos="0.0 0.0 0.0" quat="1.0 0.0 0.0 0.0" diaginertia="0.0 0.0 0.0"/>
												</body>
											</body>
										</body>
									</body>
								</body>
							</body>
						</body>
					</body>
					<body name="laser_tilt_mount_link" pos="0.0989300012588501 0.0 0.22699999809265137" quat="1.0 0.0 0.0 0.0">
						<inertial mass="0.5910000205039978" pos="-0.0011360000353306532 0.0016700000269338489 -0.0071299998089671135" quat="-0.11446588486433029 0.6666911840438843 0.043618619441986084 0.7351992130279541" diaginertia="0.0007879214826971292 0.001081750146113336 0.0012045714538544416"/>
						<joint name="laser_tilt_mount_joint" type="hinge" pos="0.0 0.0 -8.326672684688674e-17" range="-0.7854000329971313 1.483530044555664" axis="0.0 1.0 0.0"/>
						<body name="laser_tilt_link" pos="0.0 0.0 0.029201611876487732" quat="0.9999824166297913 0.0 0.0 -0.005933159962296486">
							<inertial mass="0.0010000000474974513" pos="0.0 0.0 0.0" quat="-0.7071067690849304 0.0 0.0 0.7071067690849304" diaginertia="9.999999974752427e-07 9.999999747378752e-05 9.999999747378752e-05"/>
						</body>
					</body>
					<body name="r_shoulder_pan_link" pos="0.0 -0.18799999356269836 0.0" quat="1.0 0.0 0.0 0.0">
						<inertial mass="25.7993221282959" pos="-0.0012009999481961131 0.0245130006223917 -0.0982310026884079" quat="0.31358572840690613 0.708196759223938 -0.18962126970291138 0.6034609079360962" diaginertia="0.24203263223171234 0.8377005457878113 0.9342013597488403"/>
						<joint name="r_shoulder_pan_joint" type="hinge" pos="0.0 0.0 0.0" range="-2.285398006439209 0.7146018147468567" axis="0.0 0.0 1.0"/>
						<body name="r_shoulder_lift_link" pos="0.10000000149011612 0.0 0.0" quat="1.0 0.0 0.0 0.0">
							<inertial mass="2.749880075454712" pos="0.021950000897049904 -0.026639999821782112 -0.03127000108361244" quat="0.7288599610328674 0.5471419095993042 -0.3908849358558655 -0.12887151539325714" diaginertia="0.015168089419603348 0.020730163902044296 0.026187369599938393"/>
							<joint name="r_shoulder_lift_joint" type="hinge" pos="0.0 0.0 0.0" range="-0.5235999822616577 1.3963000774383545" axis="0.0 1.0 0.0"/>
							<body name="r_upper_arm_roll_link" pos="0.0 0.0 0.0" quat="1.0 0.0 0.0 0.0">
								<inertial mass="0.10000000149011612" pos="0.0 0.0 0.0" quat="1.0 0.0 0.0 0.0" diaginertia="0.009999999776482582 0.009999999776482582 0.009999999776482582"/>
								<joint name="r_upper_arm_roll_joint" type="hinge" pos="0.0 0.0 0.0" range="-3.8999998569488525 0.800000011920929" axis="1.0 0.0 0.0"/>
								<body name="r_upper_arm_link" pos="0.0 0.0 0.0" quat="1.0 0.0 0.0 0.0">
									<inertial mass="6.017690181732178" pos="0.21398000419139862 -0.016209999099373817 -0.00019999999494757503" quat="0.9950173497200012 0.09443877637386322 -0.008656684309244156 -0.030771486461162567" diaginertia="0.015132686123251915 0.07493065297603607 0.07613848894834518"/>
									<body name="r_elbow_flex_link" pos="0.4000000059604645 0.0 0.0" quat="1.0 0.0 0.0 0.0">
										<inertial mass="1.9032700061798096" pos="0.01013999991118908 0.00031999999191612005 -0.012109999544918537" quat="0.6702385544776917 0.6546961665153503 0.23355256021022797 -0.26001229882240295" diaginertia="0.003089768812060356 0.003964767791330814 0.00441851606592536"/>
										<joint name="r_elbow_flex_joint" type="hinge" pos="0.0 0.0 0.0" range="-2.3212997913360596 0.0" axis="0.0 1.0 0.0"/>
										<body name="r_forearm_roll_link" pos="0.0 0.0 0.0" quat="1.0 0.0 0.0 0.0">
											<inertial mass="0.10000000149011612" pos="0.0 0.0 0.0" quat="1.0 0.0 0.0 0.0" diaginertia="0.009999999776482582 0.009999999776482582 0.009999999776482582"/>
											<joint name="r_forearm_roll_joint" type="hinge" pos="0.0 0.0 0.0" axis="1.0 0.0 0.0"/>
											<body name="r_forearm_cam_frame" pos="0.13918328285217285 0.0022522227372974157 0.03814560920000076" quat="0.6839321851730347 0.6789103746414185 -0.19652433693408966 0.18081943690776825">
												<inertial mass="0.009999999776482582" pos="0.0 0.0 0.0" quat="1.0 0.0 0.0 0.0" diaginertia="0.0010000000474974513 0.0010000000474974513 0.0010000000474974513"/>
												<body name="r_forearm_cam_optical_frame" pos="0.0 0.0 2.7755575615628914e-17" quat="0.5 -0.5 0.5 -0.5">
													<inertial mass="0.0" pos="0.0 0.0 0.0" quat="1.0 0.0 0.0 0.0" diaginertia="0.0 0.0 0.0"/>
												</body>
											</body>
											<body name="r_forearm_link" pos="0.0 0.0 0.0" quat="1.0 0.0 0.0 0.0">
												<inertial mass="2.5796799659729004" pos="0.18791000545024872 -0.00016999999934341758 -0.009119999594986439" quat="0.9996134638786316 0.0032210745848715305 0.0275101438164711 -0.00239151855930686" diaginertia="0.0036089171189814806 0.015077545307576656 0.01663258671760559"/>
												<body name="r_wrist_flex_link" pos="0.32100000977516174 0.0 0.0" quat="1.0 0.0 0.0 0.0">
													<inertial mass="0.6140199899673462" pos="-0.0015699999639764428 0.0 -0.000750000006519258" quat="0.40475937724113464 0.5800774693489075 -0.5794992446899414 -0.4047970473766327" diaginertia="0.00019824413175228983 0.0006433910457417369 0.0006527714431285858"/>
													<joint name="r_wrist_flex_joint" type="hinge" pos="0.0 0.0 0.0" range="-2.180000066757202 0.0" axis="0.0 1.0 0.0"/>
													<body name="r_wrist_roll_link" pos="0.0 0.0 0.0" quat="1.0 0.0 0.0 0.0">
														<inertial mass="0.10000000149011612" pos="0.0 0.0 0.0" quat="1.0 0.0 0.0 0.0" diaginertia="0.009999999776482582 0.009999999776482582 0.009999999776482582"/>
														<joint name="r_wrist_roll_joint" type="hinge" pos="0.0 0.0 0.0" axis="1.0 0.0 0.0"/>
														<body name="r_gripper_palm_link" pos="0.0 0.0 0.0" quat="1.0 0.0 0.0 0.0">
															<inertial mass="0.5800700187683105" pos="0.06622999906539917 0.0005300000193528831 -0.0011899999808520079" quat="0.9997050166130066 0.001489907270297408 -0.0008833961910568178 0.024226387962698936" diaginertia="0.000351471098838374 0.0006781778647564352 0.0008656365098431706"/>
															<body name="r_gripper_motor_accelerometer_link" pos="0.0 0.0 0.0" quat="1.0 0.0 0.0 0.0">
																<inertial mass="0.0010000000474974513" pos="0.0 0.0 0.0" quat="1.0 0.0 0.0 0.0" diaginertia="0.0010000000474974513 0.0010000000474974513 0.0010000000474974513"/>
															</body>
															<body name="r_gripper_motor_slider_link" pos="0.1682800054550171 0.0 0.0" quat="1.0 0.0 0.0 0.0">
																<inertial mass="0.009999999776482582" pos="0.0 0.0 0.0" quat="1.0 0.0 0.0 0.0" diaginertia="0.0010000000474974513 0.0010000000474974513 0.0010000000474974513"/>
																<joint name="r_gripper_motor_slider_joint" type="slide" pos="2.7755575615628914e-17 0.0 0.0" range="-0.10000000149011612 0.10000000149011612" axis="1.0 0.0 0.0"/>
																<body name="r_gripper_motor_screw_link" pos="0.0 0.0 0.0" quat="1.0 0.0 0.0 0.0">
																	<inertial mass="0.009999999776482582" pos="0.0 0.0 0.0" quat="1.0 0.0 0.0 0.0" diaginertia="9.999999747378752e-05 9.999999747378752e-05 9.999999747378752e-05"/>
																	<joint name="r_gripper_motor_screw_joint" type="hinge" pos="0.0 0.0 0.0" axis="0.0 1.0 0.0"/>
																</body>
															</body>
															<body name="r_gripper_l_finger_link" pos="0.07690999656915665 0.009999999776482582 0.0" quat="1.0 0.0 0.0 0.0">
																<inertial mass="0.17125999927520752" pos="0.03598000109195709 0.01730000041425228 -0.0016400000313296914" quat="-0.6326293349266052 0.7730244994163513 0.025774406269192696 0.03935627639293671" diaginertia="7.662394637009129e-05 0.0001813359122024849 0.00019773963140323758"/>
																<joint name="r_gripper_l_finger_joint" type="hinge" pos="-2.7755575615628914e-17 -8.673617379884035e-18 0.0" range="0.0 0.5479999780654907" axis="0.0 0.0 1.0"/>
																<body name="r_gripper_l_finger_tip_link" pos="0.09137000143527985 0.00494999997317791 0.0" quat="1.0 0.0 0.0 0.0">
																	<inertial mass="0.044190000742673874" pos="0.004230000078678131 0.002839999971911311 0.0" quat="0.9356346130371094 0.0 0.0 -0.35297003388404846" diaginertia="3.236244992876891e-06 1.5004895431047771e-05 1.5417679605889134e-05"/>
																	<joint name="r_gripper_l_finger_tip_joint" type="hinge" pos="-5.551115123125783e-17 -9.540979117872439e-18 0.0" range="0.0 0.5479999780654907" axis="0.0 0.0 -1.0"/>
																</body>
															</body>
															<body name="r_gripper_r_finger_link" pos="0.07690999656915665 -0.009999999776482582 0.0" quat="1.0 0.0 0.0 0.0">
																<inertial mass="0.17388999462127686" pos="0.035760000348091125 -0.01735999993979931 -0.0009500000160187483" quat="0.651272177696228 0.7577614188194275 -0.0200330913066864 0.035226594656705856" diaginertia="7.668467151233926e-05 0.00018134000129066408 0.00019890314433723688"/>
																<joint name="r_gripper_r_finger_joint" type="hinge" pos="-2.7755575615628914e-17 8.673617379884035e-18 0.0" range="0.0 0.5479999780654907" axis="0.0 0.0 -1.0"/>
																<body name="r_gripper_r_finger_tip_link" pos="0.09137000143527985 -0.00494999997317791 0.0" quat="1.0 0.0 0.0 0.0">
																	<inertial mass="0.044190000742673874" pos="0.004230000078678131 -0.002839999971911311 0.0" quat="0.9356346130371094 0.0 0.0 0.35297003388404846" diaginertia="3.236244992876891e-06 1.5004895431047771e-05 1.5417679605889134e-05"/>
																	<joint name="r_gripper_r_finger_tip_joint" type="hinge" pos="-5.551115123125783e-17 9.540979117872439e-18 0.0" range="0.0 0.5479999780654907" axis="0.0 0.0 1.0"/>
																</body>
															</body>
															<body name="r_gripper_led_frame" pos="0.05130000039935112 0.0 0.024399999529123306" quat="1.0 0.0 0.0 0.0">
																<inertial mass="0.0" pos="0.0 0.0 0.0" quat="1.0 0.0 0.0 0.0" diaginertia="0.0 0.0 0.0"/>
															</body>
															<body name="r_gripper_tool_frame" pos="0.18000000715255737 0.0 0.0" quat="1.0 0.0 0.0 0.0">
																<inertial mass="0.0" pos="0.0 0.0 0.0" quat="1.0 0.0 0.0 0.0" diaginertia="0.0 0.0 0.0"/>
															</body>
														</body>
													</body>
												</body>
											</body>
										</body>
									</body>
								</body>
							</body>
						</body>
					</body>
					<body name="l_shoulder_pan_link" pos="0.0 0.18799999356269836 0.0" quat="1.0 0.0 0.0 0.0">
						<inertial mass="25.7993221282959" pos="-0.0012009999481961131 0.0245130006223917 -0.0982310026884079" quat="0.31358572840690613 0.708196759223938 -0.18962126970291138 0.6034609079360962" diaginertia="0.24203263223171234 0.8377005457878113 0.9342013597488403"/>
						<joint name="l_shoulder_pan_joint" type="hinge" pos="0.0 0.0 0.0" range="-0.7146018147468567 2.285398006439209" axis="0.0 0.0 1.0"/>
						<body name="l_shoulder_lift_link" pos="0.10000000149011612 0.0 0.0" quat="1.0 0.0 0.0 0.0">
							<inertial mass="2.749880075454712" pos="0.021950000897049904 -0.026639999821782112 -0.03127000108361244" quat="0.7288599610328674 0.5471419095993042 -0.3908849358558655 -0.12887151539325714" diaginertia="0.015168089419603348 0.020730163902044296 0.026187369599938393"/>
							<joint name="l_shoulder_lift_joint" type="hinge" pos="0.0 0.0 0.0" range="-0.5235999822616577 1.3963000774383545" axis="0.0 1.0 0.0"/>
							<body name="l_upper_arm_roll_link" pos="0.0 0.0 0.0" quat="1.0 0.0 0.0 0.0">
								<inertial mass="0.10000000149011612" pos="0.0 0.0 0.0" quat="1.0 0.0 0.0 0.0" diaginertia="0.009999999776482582 0.009999999776482582 0.009999999776482582"/>
								<joint name="l_upper_arm_roll_joint" type="hinge" pos="0.0 0.0 0.0" range="-0.800000011920929 3.8999998569488525" axis="1.0 0.0 0.0"/>
								<body name="l_upper_arm_link" pos="0.0 0.0 0.0" quat="1.0 0.0 0.0 0.0">
									<inertial mass="6.017690181732178" pos="0.21404999494552612 0.016580000519752502 -0.0005699999746866524" quat="0.9944902062416077 0.10079044848680496 0.007727773394435644 0.02776307612657547" diaginertia="0.0151071073487401 0.07488211989402771 0.07606969773769379"/>
									<body name="l_elbow_flex_link" pos="0.4000000059604645 0.0 0.0" quat="1.0 0.0 0.0 0.0">
										<inertial mass="1.9032700061798096" pos="0.01013999991118908 0.00031999999191612005 -0.012109999544918537" quat="0.6702385544776917 0.6546961665153503 0.23355256021022797 -0.26001229882240295" diaginertia="0.003089768812060356 0.003964767791330814 0.00441851606592536"/>
										<joint name="l_elbow_flex_joint" type="hinge" pos="0.0 0.0 0.0" range="-2.3212997913360596 0.0" axis="0.0 1.0 0.0"/>
										<body name="l_forearm_roll_link" pos="0.0 0.0 0.0" quat="1.0 0.0 0.0 0.0">
											<inertial mass="0.10000000149011612" pos="0.0 0.0 0.0" quat="1.0 0.0 0.0 0.0" diaginertia="0.009999999776482582 0.009999999776482582 0.009999999776482582"/>
											<joint name="l_forearm_roll_joint" type="hinge" pos="0.0 0.0 0.0" axis="1.0 0.0 0.0"/>
											<body name="l_forearm_cam_frame" pos="0.14422711730003357 -0.00701887859031558 0.03542163223028183" quat="0.6808095574378967 -0.6790281534194946 -0.19713760912418365 -0.19119594991207123">
												<inertial mass="0.009999999776482582" pos="0.0 0.0 0.0" quat="1.0 0.0 0.0 0.0" diaginertia="0.0010000000474974513 0.0010000000474974513 0.0010000000474974513"/>
												<body name="l_forearm_cam_optical_frame" pos="0.0 5.551115123125783e-17 2.7755575615628914e-17" quat="0.5 -0.5 0.5 -0.5">
													<inertial mass="0.0" pos="0.0 0.0 0.0" quat="1.0 0.0 0.0 0.0" diaginertia="0.0 0.0 0.0"/>
												</body>
											</body>
											<body name="l_forearm_link" pos="0.0 0.0 0.0" quat="1.0 0.0 0.0 0.0">
												<inertial mass="2.5796799659729004" pos="0.18791000545024872 -0.00016999999934341758 -0.009119999594986439" quat="0.9996134638786316 0.0032210745848715305 0.0275101438164711 -0.00239151855930686" diaginertia="0.0036089171189814806 0.015077545307576656 0.01663258671760559"/>
												<body name="l_wrist_flex_link" pos="0.32100000977516174 0.0 0.0" quat="1.0 0.0 0.0 0.0">
													<inertial mass="0.6140199899673462" pos="-0.0015699999639764428 0.0 -0.000750000006519258" quat="0.40475937724113464 0.5800774693489075 -0.5794992446899414 -0.4047970473766327" diaginertia="0.00019824413175228983 0.0006433910457417369 0.0006527714431285858"/>
													<joint name="l_wrist_flex_joint" type="hinge" pos="0.0 0.0 0.0" range="-2.180000066757202 0.0" axis="0.0 1.0 0.0"/>
													<body name="l_wrist_roll_link" pos="0.0 0.0 0.0" quat="1.0 0.0 0.0 0.0">
														<inertial mass="0.10000000149011612" pos="0.0 0.0 0.0" quat="1.0 0.0 0.0 0.0" diaginertia="0.009999999776482582 0.009999999776482582 0.009999999776482582"/>
														<joint name="l_wrist_roll_joint" type="hinge" pos="0.0 0.0 0.0" axis="1.0 0.0 0.0"/>
														<body name="l_force_torque_adapter_link" pos="0.035599999129772186 0.0 0.0" quat="-0.7071067690849304 0.0 0.7071067690849304 0.0">
															<inertial mass="0.0" pos="0.0 0.0 0.0" quat="1.0 0.0 0.0 0.0" diaginertia="0.0 0.0 0.0"/>
															<body name="l_force_torque_link" pos="0.0 0.0 0.0" quat="0.8191520571708679 0.0 0.0 0.5735764503479004">
																<inertial mass="0.0" pos="0.0 0.0 0.0" quat="1.0 0.0 0.0 0.0" diaginertia="0.0 0.0 0.0"/>
																<body name="l_gripper_palm_link" pos="0.0 -1.1102230246251565e-16 1.1102230246251565e-16" quat="0.5792279839515686 0.4055797755718231 0.5792279839515686 -0.4055797755718231">
																	<inertial mass="0.5800700187683105" pos="0.06622999906539917 0.0005300000193528831 -0.0011899999808520079" quat="0.9997050166130066 0.001489907270297408 -0.0008833961910568178 0.024226387962698936" diaginertia="0.000351471098838374 0.0006781778647564352 0.0008656365098431706"/>
																	<body name="l_gripper_led_frame" pos="0.05130000039935112 0.0 0.024399999529123306" quat="1.0 -3.0814879110195774e-33 -3.851859888774472e-34 0.0">
																		<inertial mass="0.0" pos="0.0 0.0 0.0" quat="1.0 0.0 0.0 0.0" diaginertia="0.0 0.0 0.0"/>
																	</body>
																	<body name="l_gripper_tool_frame" pos="0.18000000715255737 2.7755575615628914e-17 1.1102230246251565e-16" quat="1.0 -3.0814879110195774e-33 -3.851859888774472e-34 0.0">
																		<inertial mass="0.0" pos="0.0 0.0 0.0" quat="1.0 0.0 0.0 0.0" diaginertia="0.0 0.0 0.0"/>
																	</body>
																	<body name="l_gripper_l_finger_link" pos="0.07690999656915665 0.009999999776482582 1.1102230246251565e-16" quat="1.0 -3.0814879110195774e-33 -3.851859888774472e-34 1.4174844390690056e-31">
																		<inertial mass="0.17125999927520752" pos="0.03598000109195709 0.01730000041425228 -0.0016400000313296914" quat="-0.6326293349266052 0.7730244994163513 0.025774406269192696 0.03935627639293671" diaginertia="7.662394637009129e-05 0.0001813359122024849 0.00019773963140323758"/>
																		<joint name="l_gripper_l_finger_joint" type="hinge" pos="-2.7755575615628914e-17 -8.673617379884035e-18 -1.1102230246251565e-16" range="0.0 0.5479999780654907" axis="0.0 0.0 1.0"/>
																		<body name="l_gripper_l_finger_tip_link" pos="0.09137000143527985 0.00494999997317791 1.1102230246251565e-16" quat="1.0 -3.0814879110195774e-33 -3.851859888774472e-34 0.0">
																			<inertial mass="0.044190000742673874" pos="0.004230000078678131 0.002839999971911311 0.0" quat="0.9356346130371094 0.0 0.0 -0.35297003388404846" diaginertia="3.236244992876891e-06 1.5004895431047771e-05 1.5417679605889134e-05"/>
																			<joint name="l_gripper_l_finger_tip_joint" type="hinge" pos="1.6653345369377348e-16 -9.540979117872439e-18 -1.1102230246251565e-16" range="0.0 0.5479999780654907" axis="0.0 0.0 -1.0"/>
																		</body>
																	</body>
																	<body name="l_gripper_motor_accelerometer_link" pos="0.0 0.0 1.1102230246251565e-16" quat="1.0 -3.0814879110195774e-33 -3.851859888774472e-34 0.0">
																		<inertial mass="0.0010000000474974513" pos="0.0 0.0 0.0" quat="1.0 0.0 0.0 0.0" diaginertia="0.0010000000474974513 0.0010000000474974513 0.0010000000474974513"/>
																	</body>
																	<body name="l_gripper_r_finger_link" pos="0.07690999656915665 -0.009999999776482582 1.1102230246251565e-16" quat="1.0 -3.0814879110195774e-33 -3.851859888774472e-34 1.4174844390690056e-31">
																		<inertial mass="0.17388999462127686" pos="0.035760000348091125 -0.01735999993979931 -0.0009500000160187483" quat="0.651272177696228 0.7577614188194275 -0.0200330913066864 0.035226594656705856" diaginertia="7.668467151233926e-05 0.00018134000129066408 0.00019890314433723688"/>
																		<joint name="l_gripper_r_finger_joint" type="hinge" pos="-2.7755575615628914e-17 -1.9081958235744878e-17 -1.1102230246251565e-16" range="0.0 0.5479999780654907" axis="0.0 0.0 -1.0"/>
																		<body name="l_gripper_r_finger_tip_link" pos="0.09137000143527985 -0.00494999997317791 1.1102230246251565e-16" quat="1.0 -3.0814879110195774e-33 -3.851859888774472e-34 0.0">
																			<inertial mass="0.044190000742673874" pos="0.004230000078678131 -0.002839999971911311 0.0" quat="0.9356346130371094 0.0 0.0 0.35297003388404846" diaginertia="3.236244992876891e-06 1.5004895431047771e-05 1.5417679605889134e-05"/>
																			<joint name="l_gripper_r_finger_tip_joint" type="hinge" pos="1.6653345369377348e-16 9.540979117872439e-18 -1.1102230246251565e-16" range="0.0 0.5479999780654907" axis="0.0 0.0 1.0"/>
																		</body>
																	</body>
																	<body name="l_gripper_motor_slider_link" pos="0.1682800054550171 2.7755575615628914e-17 1.1102230246251565e-16" quat="1.0 -3.0814879110195774e-33 -3.851859888774472e-34 1.4174844390690056e-31">
																		<inertial mass="0.009999999776482582" pos="0.0 0.0 0.0" quat="1.0 0.0 0.0 0.0" diaginertia="0.0010000000474974513 0.0010000000474974513 0.0010000000474974513"/>
																		<joint name="l_gripper_motor_slider_joint" type="slide" pos="2.7755575615628914e-17 -2.7755575615628914e-17 -1.1102230246251565e-16" range="-0.10000000149011612 0.10000000149011612" axis="1.0 0.0 0.0"/>
																		<body name="l_gripper_motor_screw_link" pos="-1.1102230246251565e-16 0.0 1.1102230246251565e-16" quat="1.0 -3.0814879110195774e-33 -3.851859888774472e-34 0.0">
																			<inertial mass="0.009999999776482582" pos="0.0 0.0 0.0" quat="1.0 0.0 0.0 0.0" diaginertia="9.999999747378752e-05 9.999999747378752e-05 9.999999747378752e-05"/>
																			<joint name="l_gripper_motor_screw_joint" type="hinge" pos="1.1102230246251565e-16 -1.771190806780867e-33 -1.1102230246251565e-16" axis="0.0 1.0 0.0"/>
																		</body>
																	</body>
																</body>
															</body>
														</body>
													</body>
												</body>
											</body>
										</body>
									</body>
								</body>
							</body>
						</body>
					</body>
					<body name="l_torso_lift_side_plate_link" pos="0.05350000038743019 0.20928500592708588 0.17662499845027924" quat="1.0 0.0 0.0 0.0">
						<inertial mass="0.10000000149011612" pos="-0.0625 0.0 0.05000000074505806" quat="1.0 0.0 0.0 0.0" diaginertia="0.0010000000474974513 0.0010000000474974513 0.0010000000474974513"/>
					</body>
					<body name="imu_link" pos="-0.029769999906420708 -0.14970000088214874 0.164000004529953" quat="-1.0341155557737347e-13 0.0 1.0 0.0">
						<inertial mass="0.0010000000474974513" pos="0.0 0.0 0.0" quat="-0.7071067690849304 0.0 0.0 0.7071067690849304" diaginertia="9.999999974752427e-07 9.999999747378752e-05 9.999999747378752e-05"/>
					</body>
				</body>
				<body name="bl_caster_rotation_link" pos="-0.22460000216960907 0.22460000216960907 0.028200000524520874" quat="1.0 0.0 0.0 0.0">
					<inertial mass="3.4730820655822754" pos="0.0 0.0 0.07000000029802322" quat="-0.4079904556274414 0.2716773748397827 0.6657471060752869 0.5625975728034973" diaginertia="0.011456840671598911 0.012544593773782253 0.015392469242215157"/>
					<joint name="bl_caster_rotation_joint" type="hinge" pos="0.0 0.0 3.469446951953614e-18" axis="0.0 0.0 1.0"/>
					<body name="bl_caster_r_wheel_link" pos="0.0 -0.04899999871850014 0.0" quat="1.0 0.0 0.0 0.0">
						<inertial mass="0.44036000967025757" pos="0.0 0.0 0.0" quat="-0.4079904556274414 0.2716773748397827 0.6657471060752869 0.5625975728034973" diaginertia="0.011456840671598911 0.012544593773782253 0.015392469242215157"/>
						<joint name="bl_caster_r_wheel_joint" type="hinge" pos="0.0 1.3877787807814457e-17 0.0" axis="0.0 1.0 0.0"/>
					</body>
					<body name="bl_caster_l_wheel_link" pos="0.0 0.04899999871850014 0.0" quat="1.0 0.0 0.0 0.0">
						<inertial mass="0.44036000967025757" pos="0.0 0.0 0.0" quat="-0.4079904556274414 0.2716773748397827 0.6657471060752869 0.5625975728034973" diaginertia="0.011456840671598911 0.012544593773782253 0.015392469242215157"/>
						<joint name="bl_caster_l_wheel_joint" type="hinge" pos="0.0 -1.3877787807814457e-17 0.0" axis="0.0 1.0 0.0"/>
					</body>
				</body>
			</body>
		</body>
	</worldbody>
	<equality>
		<joint name="r_gripper_r_finger_joint_r_gripper_l_finger_joint" joint1="r_gripper_r_finger_joint" joint2="r_gripper_l_finger_joint" polycoef="0.0 1.0 0.0 0.0 0.0"/>
		<joint name="r_gripper_r_finger_tip_joint_r_gripper_l_finger_joint" joint1="r_gripper_r_finger_tip_joint" joint2="r_gripper_l_finger_joint" polycoef="0.0 1.0 0.0 0.0 0.0"/>
		<joint name="l_gripper_l_finger_tip_joint_l_gripper_l_finger_joint" joint1="l_gripper_l_finger_tip_joint" joint2="l_gripper_l_finger_joint" polycoef="0.0 1.0 0.0 0.0 0.0"/>
		<joint name="l_gripper_r_finger_joint_l_gripper_l_finger_joint" joint1="l_gripper_r_finger_joint" joint2="l_gripper_l_finger_joint" polycoef="0.0 1.0 0.0 0.0 0.0"/>
		<joint name="r_gripper_l_finger_tip_joint_r_gripper_l_finger_joint" joint1="r_gripper_l_finger_tip_joint" joint2="r_gripper_l_finger_joint" polycoef="0.0 1.0 0.0 0.0 0.0"/>
		<joint name="l_gripper_r_finger_tip_joint_l_gripper_l_finger_joint" joint1="l_gripper_r_finger_tip_joint" joint2="l_gripper_l_finger_joint" polycoef="0.0 1.0 0.0 0.0 0.0"/>
	</equality>
</mujoco>
